reconstraining parameters Mat52.lengthscale
reconstraining parameters Mat52.variance
reconstraining parameters GP_regression.Gaussian_noise.variance
reconstraining parameters Mat52.lengthscale
reconstraining parameters Mat52.variance
reconstraining parameters GP_regression.Gaussian_noise.variance
reconstraining parameters Mat52.lengthscale
reconstraining parameters Mat52.variance
reconstraining parameters GP_regression.Gaussian_noise.variance
multiprocessing.pool.RemoteTraceback: 
"""
Traceback (most recent call last):
  File "/n/sw/eb/apps/centos7/Anaconda3/2019.10/lib/python3.7/multiprocessing/pool.py", line 121, in worker
    result = (True, func(*args, **kwds))
  File "/n/sw/eb/apps/centos7/Anaconda3/2019.10/lib/python3.7/multiprocessing/pool.py", line 44, in mapstar
    return list(map(*args))
  File "execute.py", line 217, in run_experiment
    experiment.RC_CV(cv_args = cv_args, model = model_)
  File "/n/home00/hjoy/rc/Reservoir/MARIOS/PyFiles/experiment.py", line 1179, in RC_CV
    resp_idx = dat["resp_idx"], obs_idx = dat['obs_idx'], plot = True)
  File "/n/home00/hjoy/rc/Reservoir/MARIOS/PyFiles/experiment.py", line 1207, in save_json
    else:
  File "/n/home00/hjoy/rc/Reservoir/MARIOS/PyFiles/experiment.py", line 995, in getData2Save
AttributeError: 'EchoStateExperiment' object has no attribute 'obs_kHz'
"""

The above exception was the direct cause of the following exception:

Traceback (most recent call last):
  File "execute.py", line 406, in <module>
    test(TEST = TEST)
  File "execute.py", line 391, in test
    pool.map(run_experiment, exper_)
  File "/n/sw/eb/apps/centos7/Anaconda3/2019.10/lib/python3.7/multiprocessing/pool.py", line 268, in map
    return self._map_async(func, iterable, mapstar, chunksize).get()
  File "/n/sw/eb/apps/centos7/Anaconda3/2019.10/lib/python3.7/multiprocessing/pool.py", line 657, in get
    raise self._value
AttributeError: 'EchoStateExperiment' object has no attribute 'obs_kHz'
