Process Process-1:2:
multiprocessing.pool.RemoteTraceback: 
"""
Traceback (most recent call last):
  File "/n/sw/eb/apps/centos7/Anaconda3/2019.10/lib/python3.7/multiprocessing/pool.py", line 121, in worker
    result = (True, func(*args, **kwds))
  File "/n/sw/eb/apps/centos7/Anaconda3/2019.10/lib/python3.7/multiprocessing/pool.py", line 44, in mapstar
    return list(map(*args))
  File "/n/home00/hjoy/.local/lib/python3.7/site-packages/reservoir/esn_cv.py", line 484, in define_tr_val
    validate_y[:, n].reshape(-1, 1), train_x, validate_x)
  File "/n/home00/hjoy/.local/lib/python3.7/site-packages/reservoir/esn_cv.py", line 429, in objective_function
    obs_idx = self.obs_index, resp_idx = self.target_index, plot = False, model_type = self.model_type)
  File "/n/home00/hjoy/.local/lib/python3.7/site-packages/reservoir/esn.py", line 97, in __init__
    assert self.model_type in ["exponential", "uniform", "delay_line"]
AssertionError
"""

The above exception was the direct cause of the following exception:

Traceback (most recent call last):
  File "/n/sw/eb/apps/centos7/Anaconda3/2019.10/lib/python3.7/multiprocessing/process.py", line 297, in _bootstrap
    self.run()
  File "/n/sw/eb/apps/centos7/Anaconda3/2019.10/lib/python3.7/multiprocessing/process.py", line 99, in run
    self._target(*self._args, **self._kwargs)
  File "/n/home00/hjoy/.local/lib/python3.7/site-packages/GPyOpt/util/general.py", line 149, in fun
    pipe.send(f(x))
  File "/n/home00/hjoy/.local/lib/python3.7/site-packages/GPyOpt/core/task/objective.py", line 74, in _eval_func
    rlt = self.func(np.atleast_2d(x[i]))
  File "/n/home00/hjoy/.local/lib/python3.7/site-packages/reservoir/esn_cv.py", line 537, in objective_sampler
    results = list(zip(*Pool.map(self.define_tr_val, start_indices)))#.get(timeout=5)))
  File "/n/sw/eb/apps/centos7/Anaconda3/2019.10/lib/python3.7/multiprocessing/pool.py", line 268, in map
    return self._map_async(func, iterable, mapstar, chunksize).get()
  File "/n/sw/eb/apps/centos7/Anaconda3/2019.10/lib/python3.7/multiprocessing/pool.py", line 657, in get
    raise self._value
AssertionError
Process Process-1:1:
multiprocessing.pool.RemoteTraceback: 
"""
Traceback (most recent call last):
  File "/n/sw/eb/apps/centos7/Anaconda3/2019.10/lib/python3.7/multiprocessing/pool.py", line 121, in worker
    result = (True, func(*args, **kwds))
  File "/n/sw/eb/apps/centos7/Anaconda3/2019.10/lib/python3.7/multiprocessing/pool.py", line 44, in mapstar
    return list(map(*args))
  File "/n/home00/hjoy/.local/lib/python3.7/site-packages/reservoir/esn_cv.py", line 484, in define_tr_val
    validate_y[:, n].reshape(-1, 1), train_x, validate_x)
  File "/n/home00/hjoy/.local/lib/python3.7/site-packages/reservoir/esn_cv.py", line 429, in objective_function
    obs_idx = self.obs_index, resp_idx = self.target_index, plot = False, model_type = self.model_type)
  File "/n/home00/hjoy/.local/lib/python3.7/site-packages/reservoir/esn.py", line 97, in __init__
    assert self.model_type in ["exponential", "uniform", "delay_line"]
AssertionError
"""

The above exception was the direct cause of the following exception:

Traceback (most recent call last):
  File "/n/sw/eb/apps/centos7/Anaconda3/2019.10/lib/python3.7/multiprocessing/process.py", line 297, in _bootstrap
    self.run()
  File "/n/sw/eb/apps/centos7/Anaconda3/2019.10/lib/python3.7/multiprocessing/process.py", line 99, in run
    self._target(*self._args, **self._kwargs)
  File "/n/home00/hjoy/.local/lib/python3.7/site-packages/GPyOpt/util/general.py", line 149, in fun
    pipe.send(f(x))
  File "/n/home00/hjoy/.local/lib/python3.7/site-packages/GPyOpt/core/task/objective.py", line 74, in _eval_func
    rlt = self.func(np.atleast_2d(x[i]))
  File "/n/home00/hjoy/.local/lib/python3.7/site-packages/reservoir/esn_cv.py", line 537, in objective_sampler
    results = list(zip(*Pool.map(self.define_tr_val, start_indices)))#.get(timeout=5)))
  File "/n/sw/eb/apps/centos7/Anaconda3/2019.10/lib/python3.7/multiprocessing/pool.py", line 268, in map
    return self._map_async(func, iterable, mapstar, chunksize).get()
  File "/n/sw/eb/apps/centos7/Anaconda3/2019.10/lib/python3.7/multiprocessing/pool.py", line 657, in get
    raise self._value
AssertionError
Process Process-1:5:
multiprocessing.pool.RemoteTraceback: 
"""
Traceback (most recent call last):
  File "/n/sw/eb/apps/centos7/Anaconda3/2019.10/lib/python3.7/multiprocessing/pool.py", line 121, in worker
    result = (True, func(*args, **kwds))
  File "/n/sw/eb/apps/centos7/Anaconda3/2019.10/lib/python3.7/multiprocessing/pool.py", line 44, in mapstar
    return list(map(*args))
  File "/n/home00/hjoy/.local/lib/python3.7/site-packages/reservoir/esn_cv.py", line 484, in define_tr_val
    validate_y[:, n].reshape(-1, 1), train_x, validate_x)
  File "/n/home00/hjoy/.local/lib/python3.7/site-packages/reservoir/esn_cv.py", line 429, in objective_function
    obs_idx = self.obs_index, resp_idx = self.target_index, plot = False, model_type = self.model_type)
  File "/n/home00/hjoy/.local/lib/python3.7/site-packages/reservoir/esn.py", line 97, in __init__
    assert self.model_type in ["exponential", "uniform", "delay_line"]
AssertionError
"""

The above exception was the direct cause of the following exception:

Traceback (most recent call last):
  File "/n/sw/eb/apps/centos7/Anaconda3/2019.10/lib/python3.7/multiprocessing/process.py", line 297, in _bootstrap
    self.run()
  File "/n/sw/eb/apps/centos7/Anaconda3/2019.10/lib/python3.7/multiprocessing/process.py", line 99, in run
    self._target(*self._args, **self._kwargs)
  File "/n/home00/hjoy/.local/lib/python3.7/site-packages/GPyOpt/util/general.py", line 149, in fun
    pipe.send(f(x))
  File "/n/home00/hjoy/.local/lib/python3.7/site-packages/GPyOpt/core/task/objective.py", line 74, in _eval_func
    rlt = self.func(np.atleast_2d(x[i]))
  File "/n/home00/hjoy/.local/lib/python3.7/site-packages/reservoir/esn_cv.py", line 537, in objective_sampler
    results = list(zip(*Pool.map(self.define_tr_val, start_indices)))#.get(timeout=5)))
  File "/n/sw/eb/apps/centos7/Anaconda3/2019.10/lib/python3.7/multiprocessing/pool.py", line 268, in map
    return self._map_async(func, iterable, mapstar, chunksize).get()
  File "/n/sw/eb/apps/centos7/Anaconda3/2019.10/lib/python3.7/multiprocessing/pool.py", line 657, in get
    raise self._value
AssertionError
Process Process-1:7:
multiprocessing.pool.RemoteTraceback: 
"""
Traceback (most recent call last):
  File "/n/sw/eb/apps/centos7/Anaconda3/2019.10/lib/python3.7/multiprocessing/pool.py", line 121, in worker
    result = (True, func(*args, **kwds))
  File "/n/sw/eb/apps/centos7/Anaconda3/2019.10/lib/python3.7/multiprocessing/pool.py", line 44, in mapstar
    return list(map(*args))
  File "/n/home00/hjoy/.local/lib/python3.7/site-packages/reservoir/esn_cv.py", line 484, in define_tr_val
    validate_y[:, n].reshape(-1, 1), train_x, validate_x)
  File "/n/home00/hjoy/.local/lib/python3.7/site-packages/reservoir/esn_cv.py", line 429, in objective_function
    obs_idx = self.obs_index, resp_idx = self.target_index, plot = False, model_type = self.model_type)
  File "/n/home00/hjoy/.local/lib/python3.7/site-packages/reservoir/esn.py", line 97, in __init__
    assert self.model_type in ["exponential", "uniform", "delay_line"]
AssertionError
"""

The above exception was the direct cause of the following exception:

Traceback (most recent call last):
  File "/n/sw/eb/apps/centos7/Anaconda3/2019.10/lib/python3.7/multiprocessing/process.py", line 297, in _bootstrap
    self.run()
  File "/n/sw/eb/apps/centos7/Anaconda3/2019.10/lib/python3.7/multiprocessing/process.py", line 99, in run
    self._target(*self._args, **self._kwargs)
  File "/n/home00/hjoy/.local/lib/python3.7/site-packages/GPyOpt/util/general.py", line 149, in fun
    pipe.send(f(x))
  File "/n/home00/hjoy/.local/lib/python3.7/site-packages/GPyOpt/core/task/objective.py", line 74, in _eval_func
    rlt = self.func(np.atleast_2d(x[i]))
  File "/n/home00/hjoy/.local/lib/python3.7/site-packages/reservoir/esn_cv.py", line 537, in objective_sampler
    results = list(zip(*Pool.map(self.define_tr_val, start_indices)))#.get(timeout=5)))
  File "/n/sw/eb/apps/centos7/Anaconda3/2019.10/lib/python3.7/multiprocessing/pool.py", line 268, in map
    return self._map_async(func, iterable, mapstar, chunksize).get()
  File "/n/sw/eb/apps/centos7/Anaconda3/2019.10/lib/python3.7/multiprocessing/pool.py", line 657, in get
    raise self._value
AssertionError
Process Process-1:8:
multiprocessing.pool.RemoteTraceback: 
"""
Traceback (most recent call last):
  File "/n/sw/eb/apps/centos7/Anaconda3/2019.10/lib/python3.7/multiprocessing/pool.py", line 121, in worker
    result = (True, func(*args, **kwds))
  File "/n/sw/eb/apps/centos7/Anaconda3/2019.10/lib/python3.7/multiprocessing/pool.py", line 44, in mapstar
    return list(map(*args))
  File "/n/home00/hjoy/.local/lib/python3.7/site-packages/reservoir/esn_cv.py", line 484, in define_tr_val
    validate_y[:, n].reshape(-1, 1), train_x, validate_x)
  File "/n/home00/hjoy/.local/lib/python3.7/site-packages/reservoir/esn_cv.py", line 429, in objective_function
    obs_idx = self.obs_index, resp_idx = self.target_index, plot = False, model_type = self.model_type)
  File "/n/home00/hjoy/.local/lib/python3.7/site-packages/reservoir/esn.py", line 97, in __init__
    assert self.model_type in ["exponential", "uniform", "delay_line"]
AssertionError
"""

The above exception was the direct cause of the following exception:

Traceback (most recent call last):
  File "/n/sw/eb/apps/centos7/Anaconda3/2019.10/lib/python3.7/multiprocessing/process.py", line 297, in _bootstrap
    self.run()
  File "/n/sw/eb/apps/centos7/Anaconda3/2019.10/lib/python3.7/multiprocessing/process.py", line 99, in run
    self._target(*self._args, **self._kwargs)
  File "/n/home00/hjoy/.local/lib/python3.7/site-packages/GPyOpt/util/general.py", line 149, in fun
    pipe.send(f(x))
  File "/n/home00/hjoy/.local/lib/python3.7/site-packages/GPyOpt/core/task/objective.py", line 74, in _eval_func
    rlt = self.func(np.atleast_2d(x[i]))
  File "/n/home00/hjoy/.local/lib/python3.7/site-packages/reservoir/esn_cv.py", line 537, in objective_sampler
    results = list(zip(*Pool.map(self.define_tr_val, start_indices)))#.get(timeout=5)))
  File "/n/sw/eb/apps/centos7/Anaconda3/2019.10/lib/python3.7/multiprocessing/pool.py", line 268, in map
    return self._map_async(func, iterable, mapstar, chunksize).get()
  File "/n/sw/eb/apps/centos7/Anaconda3/2019.10/lib/python3.7/multiprocessing/pool.py", line 657, in get
    raise self._value
AssertionError
Process Process-1:9:
multiprocessing.pool.RemoteTraceback: 
"""
Traceback (most recent call last):
  File "/n/sw/eb/apps/centos7/Anaconda3/2019.10/lib/python3.7/multiprocessing/pool.py", line 121, in worker
    result = (True, func(*args, **kwds))
  File "/n/sw/eb/apps/centos7/Anaconda3/2019.10/lib/python3.7/multiprocessing/pool.py", line 44, in mapstar
    return list(map(*args))
  File "/n/home00/hjoy/.local/lib/python3.7/site-packages/reservoir/esn_cv.py", line 484, in define_tr_val
    validate_y[:, n].reshape(-1, 1), train_x, validate_x)
  File "/n/home00/hjoy/.local/lib/python3.7/site-packages/reservoir/esn_cv.py", line 429, in objective_function
    obs_idx = self.obs_index, resp_idx = self.target_index, plot = False, model_type = self.model_type)
  File "/n/home00/hjoy/.local/lib/python3.7/site-packages/reservoir/esn.py", line 97, in __init__
    assert self.model_type in ["exponential", "uniform", "delay_line"]
AssertionError
"""

The above exception was the direct cause of the following exception:

Traceback (most recent call last):
  File "/n/sw/eb/apps/centos7/Anaconda3/2019.10/lib/python3.7/multiprocessing/process.py", line 297, in _bootstrap
    self.run()
  File "/n/sw/eb/apps/centos7/Anaconda3/2019.10/lib/python3.7/multiprocessing/process.py", line 99, in run
    self._target(*self._args, **self._kwargs)
  File "/n/home00/hjoy/.local/lib/python3.7/site-packages/GPyOpt/util/general.py", line 149, in fun
    pipe.send(f(x))
  File "/n/home00/hjoy/.local/lib/python3.7/site-packages/GPyOpt/core/task/objective.py", line 74, in _eval_func
    rlt = self.func(np.atleast_2d(x[i]))
  File "/n/home00/hjoy/.local/lib/python3.7/site-packages/reservoir/esn_cv.py", line 537, in objective_sampler
    results = list(zip(*Pool.map(self.define_tr_val, start_indices)))#.get(timeout=5)))
  File "/n/sw/eb/apps/centos7/Anaconda3/2019.10/lib/python3.7/multiprocessing/pool.py", line 268, in map
    return self._map_async(func, iterable, mapstar, chunksize).get()
  File "/n/sw/eb/apps/centos7/Anaconda3/2019.10/lib/python3.7/multiprocessing/pool.py", line 657, in get
    raise self._value
AssertionError
Process Process-1:10:
multiprocessing.pool.RemoteTraceback: 
"""
Traceback (most recent call last):
  File "/n/sw/eb/apps/centos7/Anaconda3/2019.10/lib/python3.7/multiprocessing/pool.py", line 121, in worker
    result = (True, func(*args, **kwds))
  File "/n/sw/eb/apps/centos7/Anaconda3/2019.10/lib/python3.7/multiprocessing/pool.py", line 44, in mapstar
    return list(map(*args))
  File "/n/home00/hjoy/.local/lib/python3.7/site-packages/reservoir/esn_cv.py", line 484, in define_tr_val
    validate_y[:, n].reshape(-1, 1), train_x, validate_x)
  File "/n/home00/hjoy/.local/lib/python3.7/site-packages/reservoir/esn_cv.py", line 429, in objective_function
    obs_idx = self.obs_index, resp_idx = self.target_index, plot = False, model_type = self.model_type)
  File "/n/home00/hjoy/.local/lib/python3.7/site-packages/reservoir/esn.py", line 97, in __init__
    assert self.model_type in ["exponential", "uniform", "delay_line"]
AssertionError
"""

The above exception was the direct cause of the following exception:

Traceback (most recent call last):
  File "/n/sw/eb/apps/centos7/Anaconda3/2019.10/lib/python3.7/multiprocessing/process.py", line 297, in _bootstrap
    self.run()
  File "/n/sw/eb/apps/centos7/Anaconda3/2019.10/lib/python3.7/multiprocessing/process.py", line 99, in run
    self._target(*self._args, **self._kwargs)
  File "/n/home00/hjoy/.local/lib/python3.7/site-packages/GPyOpt/util/general.py", line 149, in fun
    pipe.send(f(x))
  File "/n/home00/hjoy/.local/lib/python3.7/site-packages/GPyOpt/core/task/objective.py", line 74, in _eval_func
    rlt = self.func(np.atleast_2d(x[i]))
  File "/n/home00/hjoy/.local/lib/python3.7/site-packages/reservoir/esn_cv.py", line 537, in objective_sampler
    results = list(zip(*Pool.map(self.define_tr_val, start_indices)))#.get(timeout=5)))
  File "/n/sw/eb/apps/centos7/Anaconda3/2019.10/lib/python3.7/multiprocessing/pool.py", line 268, in map
    return self._map_async(func, iterable, mapstar, chunksize).get()
  File "/n/sw/eb/apps/centos7/Anaconda3/2019.10/lib/python3.7/multiprocessing/pool.py", line 657, in get
    raise self._value
AssertionError
Process Process-1:4:
multiprocessing.pool.RemoteTraceback: 
"""
Traceback (most recent call last):
  File "/n/sw/eb/apps/centos7/Anaconda3/2019.10/lib/python3.7/multiprocessing/pool.py", line 121, in worker
    result = (True, func(*args, **kwds))
  File "/n/sw/eb/apps/centos7/Anaconda3/2019.10/lib/python3.7/multiprocessing/pool.py", line 44, in mapstar
    return list(map(*args))
  File "/n/home00/hjoy/.local/lib/python3.7/site-packages/reservoir/esn_cv.py", line 484, in define_tr_val
    validate_y[:, n].reshape(-1, 1), train_x, validate_x)
  File "/n/home00/hjoy/.local/lib/python3.7/site-packages/reservoir/esn_cv.py", line 429, in objective_function
    obs_idx = self.obs_index, resp_idx = self.target_index, plot = False, model_type = self.model_type)
  File "/n/home00/hjoy/.local/lib/python3.7/site-packages/reservoir/esn.py", line 97, in __init__
    assert self.model_type in ["exponential", "uniform", "delay_line"]
AssertionError
"""

The above exception was the direct cause of the following exception:

Traceback (most recent call last):
  File "/n/sw/eb/apps/centos7/Anaconda3/2019.10/lib/python3.7/multiprocessing/process.py", line 297, in _bootstrap
    self.run()
  File "/n/sw/eb/apps/centos7/Anaconda3/2019.10/lib/python3.7/multiprocessing/process.py", line 99, in run
    self._target(*self._args, **self._kwargs)
  File "/n/home00/hjoy/.local/lib/python3.7/site-packages/GPyOpt/util/general.py", line 149, in fun
    pipe.send(f(x))
  File "/n/home00/hjoy/.local/lib/python3.7/site-packages/GPyOpt/core/task/objective.py", line 74, in _eval_func
    rlt = self.func(np.atleast_2d(x[i]))
  File "/n/home00/hjoy/.local/lib/python3.7/site-packages/reservoir/esn_cv.py", line 537, in objective_sampler
    results = list(zip(*Pool.map(self.define_tr_val, start_indices)))#.get(timeout=5)))
  File "/n/sw/eb/apps/centos7/Anaconda3/2019.10/lib/python3.7/multiprocessing/pool.py", line 268, in map
    return self._map_async(func, iterable, mapstar, chunksize).get()
  File "/n/sw/eb/apps/centos7/Anaconda3/2019.10/lib/python3.7/multiprocessing/pool.py", line 657, in get
    raise self._value
AssertionError
Process Process-1:6:
multiprocessing.pool.RemoteTraceback: 
"""
Traceback (most recent call last):
  File "/n/sw/eb/apps/centos7/Anaconda3/2019.10/lib/python3.7/multiprocessing/pool.py", line 121, in worker
    result = (True, func(*args, **kwds))
  File "/n/sw/eb/apps/centos7/Anaconda3/2019.10/lib/python3.7/multiprocessing/pool.py", line 44, in mapstar
    return list(map(*args))
  File "/n/home00/hjoy/.local/lib/python3.7/site-packages/reservoir/esn_cv.py", line 484, in define_tr_val
    validate_y[:, n].reshape(-1, 1), train_x, validate_x)
  File "/n/home00/hjoy/.local/lib/python3.7/site-packages/reservoir/esn_cv.py", line 429, in objective_function
    obs_idx = self.obs_index, resp_idx = self.target_index, plot = False, model_type = self.model_type)
  File "/n/home00/hjoy/.local/lib/python3.7/site-packages/reservoir/esn.py", line 97, in __init__
    assert self.model_type in ["exponential", "uniform", "delay_line"]
AssertionError
"""

The above exception was the direct cause of the following exception:

Traceback (most recent call last):
  File "/n/sw/eb/apps/centos7/Anaconda3/2019.10/lib/python3.7/multiprocessing/process.py", line 297, in _bootstrap
    self.run()
  File "/n/sw/eb/apps/centos7/Anaconda3/2019.10/lib/python3.7/multiprocessing/process.py", line 99, in run
    self._target(*self._args, **self._kwargs)
  File "/n/home00/hjoy/.local/lib/python3.7/site-packages/GPyOpt/util/general.py", line 149, in fun
    pipe.send(f(x))
  File "/n/home00/hjoy/.local/lib/python3.7/site-packages/GPyOpt/core/task/objective.py", line 74, in _eval_func
    rlt = self.func(np.atleast_2d(x[i]))
  File "/n/home00/hjoy/.local/lib/python3.7/site-packages/reservoir/esn_cv.py", line 537, in objective_sampler
    results = list(zip(*Pool.map(self.define_tr_val, start_indices)))#.get(timeout=5)))
  File "/n/sw/eb/apps/centos7/Anaconda3/2019.10/lib/python3.7/multiprocessing/pool.py", line 268, in map
    return self._map_async(func, iterable, mapstar, chunksize).get()
  File "/n/sw/eb/apps/centos7/Anaconda3/2019.10/lib/python3.7/multiprocessing/pool.py", line 657, in get
    raise self._value
AssertionError
Process Process-1:3:
multiprocessing.pool.RemoteTraceback: 
"""
Traceback (most recent call last):
  File "/n/sw/eb/apps/centos7/Anaconda3/2019.10/lib/python3.7/multiprocessing/pool.py", line 121, in worker
    result = (True, func(*args, **kwds))
  File "/n/sw/eb/apps/centos7/Anaconda3/2019.10/lib/python3.7/multiprocessing/pool.py", line 44, in mapstar
    return list(map(*args))
  File "/n/home00/hjoy/.local/lib/python3.7/site-packages/reservoir/esn_cv.py", line 484, in define_tr_val
    validate_y[:, n].reshape(-1, 1), train_x, validate_x)
  File "/n/home00/hjoy/.local/lib/python3.7/site-packages/reservoir/esn_cv.py", line 429, in objective_function
    obs_idx = self.obs_index, resp_idx = self.target_index, plot = False, model_type = self.model_type)
  File "/n/home00/hjoy/.local/lib/python3.7/site-packages/reservoir/esn.py", line 97, in __init__
    assert self.model_type in ["exponential", "uniform", "delay_line"]
AssertionError
"""

The above exception was the direct cause of the following exception:

Traceback (most recent call last):
  File "/n/sw/eb/apps/centos7/Anaconda3/2019.10/lib/python3.7/multiprocessing/process.py", line 297, in _bootstrap
    self.run()
  File "/n/sw/eb/apps/centos7/Anaconda3/2019.10/lib/python3.7/multiprocessing/process.py", line 99, in run
    self._target(*self._args, **self._kwargs)
  File "/n/home00/hjoy/.local/lib/python3.7/site-packages/GPyOpt/util/general.py", line 149, in fun
    pipe.send(f(x))
  File "/n/home00/hjoy/.local/lib/python3.7/site-packages/GPyOpt/core/task/objective.py", line 74, in _eval_func
    rlt = self.func(np.atleast_2d(x[i]))
  File "/n/home00/hjoy/.local/lib/python3.7/site-packages/reservoir/esn_cv.py", line 537, in objective_sampler
    results = list(zip(*Pool.map(self.define_tr_val, start_indices)))#.get(timeout=5)))
  File "/n/sw/eb/apps/centos7/Anaconda3/2019.10/lib/python3.7/multiprocessing/pool.py", line 268, in map
    return self._map_async(func, iterable, mapstar, chunksize).get()
  File "/n/sw/eb/apps/centos7/Anaconda3/2019.10/lib/python3.7/multiprocessing/pool.py", line 657, in get
    raise self._value
AssertionError
