multiprocessing.pool.RemoteTraceback: 
"""
Traceback (most recent call last):
  File "/n/sw/eb/apps/centos7/Anaconda3/2019.10/lib/python3.7/multiprocessing/pool.py", line 121, in worker
    result = (True, func(*args, **kwds))
  File "/n/sw/eb/apps/centos7/Anaconda3/2019.10/lib/python3.7/multiprocessing/pool.py", line 44, in mapstar
    return list(map(*args))
  File "/n/home00/hjoy/rc/Reservoir/MARIOS/execute_scripts/column.py", line 155, in run_experiment
    experiment.RC_CV(cv_args = cv_args, model = "uniform")
  File "/n/home00/hjoy/rc/Reservoir/MARIOS/PyFiles/experiment.py", line 1175, in RC_CV
    obs_idx  = predetermined_args['obs_index'],
UnboundLocalError: local variable 'predetermined_args' referenced before assignment
"""

The above exception was the direct cause of the following exception:

Traceback (most recent call last):
  File "execute.py", line 258, in <module>
    test(TEST = TEST)
  File "execute.py", line 240, in test
    pool.map(run_experiment, exper_)
  File "/n/sw/eb/apps/centos7/Anaconda3/2019.10/lib/python3.7/multiprocessing/pool.py", line 268, in map
    return self._map_async(func, iterable, mapstar, chunksize).get()
  File "/n/sw/eb/apps/centos7/Anaconda3/2019.10/lib/python3.7/multiprocessing/pool.py", line 657, in get
    raise self._value
UnboundLocalError: local variable 'predetermined_args' referenced before assignment
multiprocessing.pool.RemoteTraceback: 
"""
Traceback (most recent call last):
  File "/n/sw/eb/apps/centos7/Anaconda3/2019.10/lib/python3.7/multiprocessing/pool.py", line 121, in worker
    result = (True, func(*args, **kwds))
  File "/n/sw/eb/apps/centos7/Anaconda3/2019.10/lib/python3.7/multiprocessing/pool.py", line 44, in mapstar
    return list(map(*args))
  File "/n/home00/hjoy/rc/Reservoir/MARIOS/execute_scripts/column.py", line 155, in run_experiment
    experiment.RC_CV(cv_args = cv_args, model = "uniform")
  File "/n/home00/hjoy/rc/Reservoir/MARIOS/PyFiles/experiment.py", line 1175, in RC_CV
    obs_idx  = predetermined_args['obs_index'],
UnboundLocalError: local variable 'predetermined_args' referenced before assignment
"""

The above exception was the direct cause of the following exception:

Traceback (most recent call last):
  File "execute.py", line 260, in <module>
    print('Time: ', stop - start) 
  File "execute.py", line 242, in test
    pool.join()
  File "/n/sw/eb/apps/centos7/Anaconda3/2019.10/lib/python3.7/multiprocessing/pool.py", line 268, in map
    return self._map_async(func, iterable, mapstar, chunksize).get()
  File "/n/sw/eb/apps/centos7/Anaconda3/2019.10/lib/python3.7/multiprocessing/pool.py", line 657, in get
    raise self._value
UnboundLocalError: local variable 'predetermined_args' referenced before assignment
reconstraining parameters Mat52.lengthscale
reconstraining parameters Mat52.variance
reconstraining parameters GP_regression.Gaussian_noise.variance
