reconstraining parameters Mat52.lengthscale
reconstraining parameters Mat52.variance
reconstraining parameters GP_regression.Gaussian_noise.variance
multiprocessing.pool.RemoteTraceback: 
"""
Traceback (most recent call last):
  File "/n/sw/eb/apps/centos7/Anaconda3/2019.10/lib/python3.7/multiprocessing/pool.py", line 121, in worker
    result = (True, func(*args, **kwds))
  File "/n/sw/eb/apps/centos7/Anaconda3/2019.10/lib/python3.7/multiprocessing/pool.py", line 44, in mapstar
    return list(map(*args))
  File "/n/home00/hjoy/rc/Reservoir/MARIOS/execute_scripts/column.py", line 155, in run_experiment
    experiment.RC_CV(cv_args = cv_args, model = "uniform")
  File "/n/home00/hjoy/rc/Reservoir/MARIOS/PyFiles/experiment.py", line 1185, in RC_CV
    self.prediction = my_predict(self.Test)
  File "/n/home00/hjoy/rc/Reservoir/MARIOS/PyFiles/experiment.py", line 1183, in my_predict
    return self.esn.predict(n_steps, x = test[:n_steps,:])
  File "/n/home00/hjoy/.local/lib/python3.7/site-packages/reservoir/esn.py", line 463, in predict
    x = self.normalize(inputs=x)
  File "/n/home00/hjoy/.local/lib/python3.7/site-packages/reservoir/esn.py", line 236, in normalize
    transformed.append((inputs - self._input_means) / self._input_stds)
ValueError: operands could not be broadcast together with shapes (40,1103) (51,) 
"""

The above exception was the direct cause of the following exception:

Traceback (most recent call last):
  File "execute.py", line 258, in <module>
    test(TEST = TEST)
  File "execute.py", line 240, in test
    pool.map(run_experiment, exper_)
  File "/n/sw/eb/apps/centos7/Anaconda3/2019.10/lib/python3.7/multiprocessing/pool.py", line 268, in map
    return self._map_async(func, iterable, mapstar, chunksize).get()
  File "/n/sw/eb/apps/centos7/Anaconda3/2019.10/lib/python3.7/multiprocessing/pool.py", line 657, in get
    raise self._value
ValueError: operands could not be broadcast together with shapes (40,1103) (51,) 
