multiprocessing.pool.RemoteTraceback: 
"""
Traceback (most recent call last):
  File "/n/sw/eb/apps/centos7/Anaconda3/2019.10/lib/python3.7/multiprocessing/pool.py", line 121, in worker
    result = (True, func(*args, **kwds))
  File "/n/sw/eb/apps/centos7/Anaconda3/2019.10/lib/python3.7/multiprocessing/pool.py", line 44, in mapstar
    return list(map(*args))
  File "/n/home00/hjoy/rc/Reservoir/MARIOS/execute_scripts/column.py", line 60, in run_experiment
    print("Prediction Type: " + inputs["prediction_type"])
KeyError: 'prediction_type'
"""

The above exception was the direct cause of the following exception:

Traceback (most recent call last):
  File "execute_dl.py", line 212, in <module>
    test(TEST = TEST)
  File "execute_dl.py", line 196, in test
    pool.map(run_experiment, exper_)
  File "/n/sw/eb/apps/centos7/Anaconda3/2019.10/lib/python3.7/multiprocessing/pool.py", line 268, in map
    return self._map_async(func, iterable, mapstar, chunksize).get()
  File "/n/sw/eb/apps/centos7/Anaconda3/2019.10/lib/python3.7/multiprocessing/pool.py", line 657, in get
    raise self._value
KeyError: 'prediction_type'
