multiprocessing.pool.RemoteTraceback: 
"""
Traceback (most recent call last):
  File "/n/sw/eb/apps/centos7/Anaconda3/2019.10/lib/python3.7/multiprocessing/pool.py", line 121, in worker
    result = (True, func(*args, **kwds))
  File "/n/sw/eb/apps/centos7/Anaconda3/2019.10/lib/python3.7/multiprocessing/pool.py", line 44, in mapstar
    return list(map(*args))
  File "/n/home00/hjoy/rc/Reservoir/MARIOS/execute_scripts/column.py", line 174, in run_experiment
    experiment.RC_CV(cv_args = cv_args, model = "cyclic")
  File "/n/home00/hjoy/rc/Reservoir/MARIOS/PyFiles/experiment.py", line 1196, in RC_CV
    self.best_arguments['feedback'] = False
AttributeError: 'EchoStateExperiment' object has no attribute 'best_arguments'
"""

The above exception was the direct cause of the following exception:

Traceback (most recent call last):
  File "execute_cyclic.py", line 223, in <module>
    test(TEST = TEST)
  File "execute_cyclic.py", line 207, in test
    pool.map(run_experiment, exper_)
  File "/n/sw/eb/apps/centos7/Anaconda3/2019.10/lib/python3.7/multiprocessing/pool.py", line 268, in map
    return self._map_async(func, iterable, mapstar, chunksize).get()
  File "/n/sw/eb/apps/centos7/Anaconda3/2019.10/lib/python3.7/multiprocessing/pool.py", line 657, in get
    raise self._value
AttributeError: 'EchoStateExperiment' object has no attribute 'best_arguments'
